{
 "cells": [
  {
   "cell_type": "code",
   "execution_count": 3,
   "id": "35982aa0",
   "metadata": {},
   "outputs": [
    {
     "name": "stdout",
     "output_type": "stream",
     "text": [
      "\\Untitled.ipynb : 0.0009527206420898438  мегобайт  2024-06-20 12:00:39.102205\n"
     ]
    }
   ],
   "source": [
    "import os;import math;import sys;import datetime;\n",
    "var='\\\\Untitled.ipynb'\n",
    "print (var,':',os.path.getsize(os.path.abspath(os.curdir)+var)/math.pow(2, 20),' мегобайт ',datetime.datetime.now())"
   ]
  },
  {
   "cell_type": "markdown",
   "id": "fc3df04e",
   "metadata": {},
   "source": [
    "В листингах 13.3 и 13.4 устранена проблема, проявившаяся на рис. 13.3. Посмотрите на последний сеанс программы. Пользователь ввел отрицательное число, и компьютер, не моргнув глазом, принял введенное значение. Но ведь для того, чтобы на полке вашего склада могло оказаться отрицательное количество ящиков с товаром, местом вашего обитания должна быть, вероятно, черная дыра или еще какой-нибудь экзотический пространственно-временной континуум. Поэтому нам следует позаботиться о том, чтобы программа замечала ввод отрицательных чисел, что и сделано в листинге 13.4. Результат показан на рис. 13.5.\n",
    "\n",
    "    Сколько коробок вы насчитали? Общая стоимость равна: 9,75 руб.\n",
    "    Сколько коробок вы насчитали? три Это не число.\n",
    "    Сколько коробок вы насчитали? -25? Это невозможно!\n",
    "    -25\n",
    "Рис. 13.5. Три сеанса программы, приведенной в листингах 13.3 и 13.4\n",
    "\n",
    "В листинге 13.3 объявлен новый вид пользовательского исключения: OutOfRangeException. Вы можете присвоить ему произвольное имя, однако в Java принято заканчивать имя исключения словом Exception. Во многих ситуациях ввод отрицательных чисел не является ошибкой, поэтому данное исключение не встроено в Java API. Но в нашем примере отрицательное число недопустимо.\n",
    "\n",
    "Стр. 391\n",
    "\n",
    "----------"
   ]
  },
  {
   "cell_type": "markdown",
   "id": "f2bd3844",
   "metadata": {},
   "source": [
    "Класс OutOfRangeException в листинге 13.3 по праву может считаться pe- кордсменом по краткости кода в данной книге. Код класса состоит всего лишь из заголовка и пары фигурных скобок, между которыми ничего нет. Наиболее содержательная фраза extends Exception означает, что пользовательский класс является производным от класса Exception, который определен в Java API.\n",
    "В листинге 13.4 код в случае генерирования исключения с помощью ключевого слова throw создает экземпляр класса OutOfRangeException. Если это происходит, указанный экземпляр перехватывается блоком catch, который отображает на консоли пользовательский ввод вместе с сообщением \"Это невозможно!\"\n",
    "- перекрестная ссылка - Текст @SuppressWarnings (\"serial\") в листинге 13.3 - это аннотация Java. Краткие сведения об аннотациях приведены в главе 8. Аннотация @SuppressWarnings (отменить предупреждения) рассматривалась в главе 9.\n",
    "- технические подробности - Пользователи рабочей среды Eclipse могут увидеть желтый маркер предупреждения, который отображается рядом с новой строкой OutOfRangeException () в листинге 13.4. Если установить указатель мыши над предупреждающим маркером, Eclipse выведет следующее cообщение: Resource leak: 'keyboard' is not closed at this location (Утечка ресурсов: 'клавиатура' не закрыта в этом месте). Eclipse постоянно пытается убедиться в том, что ваш код в конечном итогe выполняет инструкцию keyboard.close(). (Да, при определенных обстоятельствах генерирование исключения OutOfRangeException может привести к тому, что программа пропустит инструкцию keyboard.close (). Но нет, этого не произойдет, если вы запустите код из листинга 13.4.) Как мне кажется, это предупреждение можно спокойно игнорировать."
   ]
  },
  {
   "cell_type": "markdown",
   "id": "41994048",
   "metadata": {},
   "source": [
    "# Кто должен перехватить исключение\n",
    "Посмотрите еще раз на листинг 13.4. Обратите внимание на то, что с блоком try может быть aссоциировано несколько блоков catch. Когда в блоке try re- нерируется исключение, компьютер просматривает список блоков catch сверху\n",
    "вниз.Просматривая каждый блок catch, компьютер проверяет, является ли сгенерированное исключение экземпляром класса исключения, указанного в списке параметров данного блока catch.\n",
    "- Кто должен перехватить исключение\n",
    "- Посмотрите еще раз на листинг 13.4. Обратите внимание на то, что с блоком try может быть aссоциировано несколько блоков catch. Когда в блоке try re-нерируется исключение, компьютер просматривает список блоков catch сверху\n",
    "вниз.\n",
    "- Просматривая каждый блок catch, компьютер проверяет, является ли сгенерированное исключение экземпляром класса исключения, указанного в списке параметров данного блока catch.\n",
    "\n",
    "Стр. 392\n",
    "\n",
    "-------"
   ]
  },
  {
   "cell_type": "markdown",
   "id": "a6a6d29e",
   "metadata": {},
   "source": [
    "    Конкретные примеры приведены в листингах 13.5 и 13.6.\n",
    "    Листинг 13.5. Еще одно исключение\n",
    "    @SuppressWarnings (\"serial\")\n",
    "    class NumberTooLargeException extends OutOfRangeException {}"
   ]
  },
  {
   "cell_type": "markdown",
   "id": "c1257477",
   "metadata": {},
   "source": [
    "    Листинг 13.6. Кто обработает исключение?\n",
    "    import static java.lang.System.out;\n",
    "    import java.util.Scanner;\n",
    "    import java.text.NumberFormat;\n",
    "    public class InventoryD \n",
    "    {\n",
    "        public static void main(String args[])\n",
    "        {\n",
    "            final double boxPrice = 3.25;\n",
    "            Scanner keyboard = new Scanner (System.in);\n",
    "            NumberFormat currency = NumberFormat.getCurrencyInstance();\n",
    "            out.print(\"Сколько коробок вы насчитали? \");\n",
    "            String numBoxesIn = keyboard.next ();\n",
    "            try \n",
    "            {\n",
    "                int numBoxes = Integer.parseInt (numBoxesIn);\n",
    "                if (numBoxes < 0) { throw new OutOfRangeException () ;}\n",
    "                if (numBoxes > 1000) { throw new NumberTooLargeException() ;}\n",
    "                out. print (\"Общая стоимость равна: \");\n",
    "                out.println(currency.format (numBoxes * boxPrice));\n",
    "            }"
   ]
  },
  {
   "cell_type": "markdown",
   "id": "313e8c49",
   "metadata": {},
   "source": [
    "\n",
    "            catch (NumberFormatException e) ( out.println(\"Это не число.\");\n",
    "            \n",
    "            catch (OutOfRangeException e) \n",
    "            {\n",
    "                out.print(numBoxesIn);\n",
    "                out.println(\"? Это невозможно!\");\n",
    "            }\n",
    "            catch (Exception e)\n",
    "            {\n",
    "                out.print(\"Что-то здесь не так, \");\n",
    "                out.print (\"но что именно, непонятно.\");\n",
    "                out.println(\"Тип исключения неизвестен.\");\n",
    "            }\n",
    "            out.println(\"Вышли из блоков try-catch.\");\n",
    "            keyboard.close();\n",
    "        }\n",
    "    }\n",
    "Стр. 393"
   ]
  },
  {
   "cell_type": "markdown",
   "id": "564ea7f3",
   "metadata": {},
   "source": [
    "Кроме листингов 13.5 и 13.6, в данной программе используется класс OutOf RangeException, приведенный в листинге 13.3.\n",
    "В листинге 13.6 имитируется сценарий, в котором на вашем складе ограничено пространство. Вы не можете хранить более тысячи коробок одновременно, поэтому нужно проверить, превышает ли значение numBoxes этот порог. Если\n",
    "превышает, программа генерирует исключение NumberTooLargeException.\n",
    "Чтобы сделать жизнь немного интереснее, в листинге 13.6 нет блока catch для исключения NumberTooLargeException. Несмотря на это программа заметила, что коробок слишком много, и сообщила об этом пользователю (рис. 13.6). Как это произошло? Дело в том, что класс исключения NumberTooLargeException наследует класс исключения OutOfRangeException (см. листинг 13.5). Сгене- рировав исключение NumberTooLargeException, компьютер проходит по списку блоков catch. Дойдя до блока OutOfRangeException, компьютер видит, что этот класс наследуется исключением NumberTooLargeException, и принимает решение обработать его в данном блоке. Следовательно, блок catch перехватывает исключение не только тогда, когда оно есть в списке его параметров, но и когда оно наследует исключение, приведенное в списке его параметров.\n",
    "Чтобы не городить снова и снова громоздкие описания, введем новые термины. Будем говорить, что инструкция catch с параметром OutOfRangeException coоmвеmствуеm cгенерированному исключению NumberTooLargeException. Эта инструкция будет называться соответствующим блоком catch.\n",
    "Ниже описаны разнообразные действия пользователей и реакция компьютера в ответ на эти действия. По ходу чтения можете просматривать результаты, представленные на рис. 13.6.\n",
    "\n",
    "Стр. 394\n",
    "\n",
    "----------"
   ]
  },
  {
   "cell_type": "markdown",
   "id": "7509513d",
   "metadata": {},
   "source": [
    "    Сколько коробок вы насчитали? Общая стоимость равна: 9,75 руб. Вышли из блоков try-catch.\n",
    "    Сколько коробок вы насчитали? рыба Это не число.\n",
    "    Вышли из блоков try-catch.\n",
    "    Сколько коробок вы насчитали? -25 -25? Это невозможно!\n",
    "    Вышли из блоков try-catch.\n",
    "    Сколько коробок вы насчитали? 10e1 1001? Это невозможно!\n",
    "    Вышли из блоков try-catch.\n",
    "Рис. 13.6. Четыре сеанса работы листинга 13.6\n",
    "\n",
    "- Пользователь вводит корректное целое число, например 3. Все инструкции блока try выполняются. После этого компьютер пропускает все блоки catch и выполняет первую инструкцию, расположенную непосредственно после них (рис. 13.7)."
   ]
  },
  {
   "cell_type": "markdown",
   "id": "23c7c96b",
   "metadata": {},
   "source": [
    "    try (\n",
    "        //Нормальное виполнение (без исключений)\n",
    "    }\n",
    "    catch (NumberFormatException e){ out.println(\"Это не число.\");}\n",
    "    catch (OutOfRangeException e){ outprint (numBoxesIn) ; out.println(\"? Это невозможно!\");}\n",
    "    catch (Exception e)\n",
    "    {\n",
    "        out.print (\"Что-то здесь не так, \");\n",
    "        out.print (\"но что именно, непонятно.\");\n",
    "        out.println(\"Тип исключения неизвестен.\");\n",
    "    }\n",
    "    out.println (\"Вышли из блоков try-catch.\");\n",
    "    \n",
    "Рис. 13.7. Не сгенерировано ни одного исключения"
   ]
  },
  {
   "cell_type": "markdown",
   "id": "b3999d34",
   "metadata": {},
   "source": [
    "- Пользователь вводит фразу, которая не является числом, например слово рыба. Виртуальная машина Java генерирует исключение NumberFormatException. Компьютер пропускает оставшуюся часть блока try и выполняет блок catch, в списке параметров которого есть класс NumberFormatException. После этого компьютер пропускает остальные блоки catch и выполняет инструкцию, расположенную непосредственно после них (рис. 13.8).\n",
    "\n",
    "Стр. 395 - 396 - Барри вот честно, у тебя там 3 страницы одинаковые. Классная опечатка!\n",
    "\n",
    "---------"
   ]
  },
  {
   "cell_type": "markdown",
   "id": "65c1ae1d",
   "metadata": {},
   "source": [
    "Пользователь вводит слишком большое число, например 1001. Программа генерирует исключение NumberTooLargeException. Компьютер пропускает оставшиеся инструкции блока try и первый блок catch (потому что исключение NumberTooLargeException несовместимо с исключением NumberFormatException, указанным в списке параметров первого блока catch).\n",
    "В соответствии с объявлением класса NumberTooLargeException в листинге 13.5 он наследует класс OutOfRangeException. Когда компьютер доходит до второго блока catch, он видит, что класс текущего исключения наследует класс параметра блока catch. Другими словами, в данном случае речь идет о соответствующем блоке catch.\n",
    "В итоге компьютер выполняет второй блок catch, после этого пропускает третий блок catch и выполняет инструкцию, расположенную после него (рис. 13.10).\n",
    "\n",
    "»\n",
    "В блоке try происходит нечто непредвиденное, например возникает ошибка ввода-вывода и генерируется исключение IOException. В принципе, в данном листинге этого не может произойти, однако для эксперимента сгенерируем исключение IOException искусственно и посмотрим, что произойдет. Это можно сделать с помощью инструкции throw new IOException ().\n",
    "Когда код сгенерирует исключение IOException, компьютер пропустит оставшиеся инструкции блока try и два первых блока catch, потому что они не имеют отношения к данному исключению.\n",
    "\n",
    "Стр. 397\n",
    "\n",
    "------"
   ]
  },
  {
   "cell_type": "markdown",
   "id": "d9aa36cd",
   "metadata": {},
   "source": [
    "Подойдя к третьему блоку catch, компьютер обнаружит, что текущее исключение наследует исключение Exception, которое является базовым для всех классов исключений.\n",
    "Поэтому компьютер выполнит третий блок catch и перейдет к выполнению инструкции, расположенной непосредственно после него (рис. 13.11).Теперь мы можем сформулировать общее правило выбора подходящего блока catch. Когда блок try генерирует исключение и компьютер ищет подходящий блок catch, он выбирает первый сверху блок, удовлетворяющий одному из следующих условий:\n",
    "\n",
    "- класс параметра блока catch совпадает с классом текущего исключения;\n",
    "- класс параметра блока catch является базовым для класса текущего исключения.\n",
    "\n",
    "Если ниже в списке есть лучшее совпадение, компьютер не найдет его. Предположим, вы добавили блок catch с параметром типа NumberTooLargeException, но не до, а после блока catch с параметром OutOfRangeException. Тогда при возникновении исключения NumberTooLargeException компьютер выполнит блок с параметром OutOfRangeException, хотя есть блок с параметром, тип которого точно совпадает с типом текущего исключения.\n",
    "\n",
    "Стр. 398\n",
    "\n",
    "------"
   ]
  },
  {
   "cell_type": "markdown",
   "id": "d00fafd0",
   "metadata": {},
   "source": [
    "# Блок catch с несколькими типами исключений\n",
    "Начиная с версии Java 7 допускается перехват нескольких исключений в одном блоке catch. Предположим, в предыдущем примере вы не хотите проводить никаких различий между исключениями NumberFormatException и OutOfRangeException. В таком случае можно переписать часть листинга 13.6 следующим образом."
   ]
  },
  {
   "cell_type": "markdown",
   "id": "4d5c6caf",
   "metadata": {},
   "source": [
    "    try {\n",
    "        int numBoxes = Integer.parseInt (numBoxesIn);\n",
    "        if (numBoxes < 0){throw new OutOfRangeException();}\n",
    "        if (numBoxes > 1000) { throw new NumberTooLargeException();}\n",
    "        out.print(\"Общая стоимость равна: \");\n",
    "        out.println(currency.format (numBoxes * boxPrice));\n",
    "    }\n",
    "    catch (NumberFormatException | OutOfRangeException e) \n",
    "    {\n",
    "        out.print (numBoxesIn);\n",
    "        out. println(\"? Это невозможно!\");\n",
    "    }\n",
    "    catch (Exception e)\n",
    "    {\n",
    "        out.print(\"Что-то здесь не так, \");\n",
    "        out.print (\"но что именно, непонятно.\");\n",
    "        out.println(\"Тип исключения неизвестен.\");\n",
    "    }"
   ]
  },
  {
   "cell_type": "markdown",
   "id": "edbabffb",
   "metadata": {},
   "source": [
    "Символ | сообщает Java о том, что блок должен перехватить исключение, принадлежащее к любому из указанных типов: NumberFormatException или OutOfRangeException. Если блок try crенерирует исключение любого из этих типов, компьютер отобразит сообщение Это невозможно!. Если же блок try сгенерирует исключение какого-то другого типа, будет выполнен следующий блок catch, потому что исключение Exception является базовым для исключений любого типа.\n",
    "\n",
    "Стр. 399\n",
    "\n",
    "---------"
   ]
  },
  {
   "cell_type": "markdown",
   "id": "c3274470",
   "metadata": {},
   "source": [
    "# Не будем чрезмерно осторожничать\n",
    "Персонаж рассказа А. П. Чехова \"Человек в футляре\" всегда, даже в солнечный день, ходил с зонтиком, на случай, если вдруг пойдет дождь, и часто повторял фразу \"Как бы чего не вышло\". Должны ли мы применить подобный подход и попытаться заранее запрограммировать перехват любых возможных исключений? Видимо, нет. Все хорошо в меру. К тому же компилятор Java не позволяет нам впасть в паранойю и отказывается компилировать код, перехва- тывающий исключения, которые не могут произойти.\n",
    "Предположим, в блоке try находится безобидная инструкция i++. Это вполне допустимо. Однако рассмотрим, что будет, если блок catch попытается перехватить исключение IOException (исключение ввода-вывода), которое в инструкции і++ не может произойти.\n",
    "\n",
    "    // Неправильный код!\n",
    "    try { i++; } catch (IOException e) { e.printStackTrace ();}\n",
    "    \n",
    "Чем же примечателен этот код? Инструкция i++ не выполняет операции ввода-вывода, поэтому в блоке try не может произойти исключение IOException. Компилятор отреагирует на это тем, что откажется запустить программу на выполнение и отобразит следующее сообщение.\n",
    "\n",
    "    Exception java.io.IOException is never thrown\n",
    "    in body of corresponding try statement\n",
    "    (Исключение java.io.IOException не может быть creнерировано\n",
    "    в данной инструкции try)"
   ]
  },
  {
   "cell_type": "markdown",
   "id": "5426031b",
   "metadata": {},
   "source": [
    "# Восстановление работы программы после генерирования исключения\n",
    "В предыдущих примерах блок catch выводил на консоль сообщение об ошибке, и на этом спектакль заканчивался. Конечно, было бы лучше, если бы программа не только сообщила об ошибке, но и предоставила пользователю возможность ее исправить. Но как это сделать? Ведь после блока catch управление не возвращается в блок try. Решение состоит в том, чтобы заключить блоки try и catch в цикл (листинг 13.7). Тогда все будет повторяться с самого начала, пока пользователь не введет правильные данные.\n",
    "\n",
    "Стр. 400"
   ]
  }
 ],
 "metadata": {
  "kernelspec": {
   "display_name": "Python 3 (ipykernel)",
   "language": "python",
   "name": "python3"
  },
  "language_info": {
   "codemirror_mode": {
    "name": "ipython",
    "version": 3
   },
   "file_extension": ".py",
   "mimetype": "text/x-python",
   "name": "python",
   "nbconvert_exporter": "python",
   "pygments_lexer": "ipython3",
   "version": "3.11.4"
  }
 },
 "nbformat": 4,
 "nbformat_minor": 5
}
